Workbook

Sheet monopolio
H1: Competencia perfecta
B2: Competencia perfecta | H2: CSP | I2: =C3*E6-0.5*C4*E6^2-E6*G5 -> 40 | P2: =C3*E6-0.5*C4*E6^2 -> 160
B3: PDMX | C3: 100 | D3: Qg1 | E3: 1 | H3: PSP1 | I3: =E3*G5-(C5*E3+0.5*C6*E3*E3) -> 45.000001 | P3: =-(C5*E3+0.5*C6*E3*E3) -> -15
B4: mD | C4: 20 | D4: Qg2 | E4: 0.99999998 | H4: PSP2 | I4: =E4*G5-(C7*E4+0.5*C8*E4*E4) -> 47.499999 | J4: beta= | K4: =J5*2/E6 -> 92.5 | N4: =SUM(M3:M4) -> 0 | P4: =-(C7*E4+0.5*C8*E4*E4) -> -12.5
B5: PG1min | C5: 10 | E5: =SUM(E3:E4) -> 2 | F5: P* | G5: =C3-C4*E6 -> 60 | H5: SW | I5: =SUM(I2:I4) -> 132.5 | J5: =SUM(I3:I4) -> 92.5 | P5: =SUM(P2:P4) -> 132.5 | Q5: =SUM(P3:P4) -> -27.5
B6: mO1 | C6: 10 | D6: Qd | E6: 2 | F6: Pm
B7: PG2min | C7: 5 | D7: Qm | E7: =G7+G8 -> 0 | F7: Qm1 | J7: Perdida de eficiencia | M7: =I5-M5 -> 132.5
B8: mO2 | C8: 15 | F8: Qm2
B9: TC1 | C9: =C5*E3+0.5*C6*E3^2 -> 15
B10: TC2 | C10: =C7*E4+0.5*C8*E4^2 -> 12.5 | E10: Multiplicador de Lagrange
B11: U | C11: =C3*E6-0.5*C4*E6*E6 -> 160 | E11: l | F11: 29.230769 | G11: =C5+C6*F12-F11 -> 1.2232372e-07
B12: SW | C12: =C11-C9-C10 -> 132.5 | E12: Q1 | F12: 1.9230769 | G12: =C7+C8*F13-F11 -> -2.4697031e-07
B13: Pgmin eq | C13: =G5-2*(I3+I4)/E6 -> -32.5 | E13: Q2 | F13: 1.6153846 | G13: =C3-C4*F14-F11 -> 0
B14: mOeq | C14: =(G5-C13)/E6 -> 46.25 | E14: QD | F14: 3.5384615 | G14: =F14-F13-F12 -> 4.8849813e-15
C16: Qg | D16: Bmarg | E16: MC1 | F16: MC2 | G16: P* | H16: eq | I16: Pm
C17: 0 | D17: =$C$3-C$4*C17 -> 100 | E17: =$C$5+$C$6*C17 -> 10 | F17: =$C$7+$C$8*C17 -> 5 | G17: =$G$5 -> 60 | H17: =$C$13+C17*$C$14 -> -32.5 | I17: =Oligo!$J$16 -> 48.936171
C18: 0.2 | D18: =$C$3-C$4*C18 -> 96 | E18: =$C$5+$C$6*C18 -> 12 | F18: =$C$7+$C$8*C18 -> 8 | G18: =$G$5 -> 60 | H18: =$C$13+C18*$C$14 -> -23.25 | I18: =Oligo!$J$16 -> 48.936171
C19: 0.4 | D19: =$C$3-C$4*C19 -> 92 | E19: =$C$5+$C$6*C19 -> 14 | F19: =$C$7+$C$8*C19 -> 11 | G19: =$G$5 -> 60 | H19: =$C$13+C19*$C$14 -> -14 | I19: =Oligo!$J$16 -> 48.936171
C20: 0.6 | D20: =$C$3-C$4*C20 -> 88 | E20: =$C$5+$C$6*C20 -> 16 | F20: =$C$7+$C$8*C20 -> 14 | G20: =$G$5 -> 60 | H20: =$C$13+C20*$C$14 -> -4.75 | I20: =Oligo!$J$16 -> 48.936171
C21: 0.8 | D21: =$C$3-C$4*C21 -> 84 | E21: =$C$5+$C$6*C21 -> 18 | F21: =$C$7+$C$8*C21 -> 17 | G21: =$G$5 -> 60 | H21: =$C$13+C21*$C$14 -> 4.5 | I21: =Oligo!$J$16 -> 48.936171 | L21: =2*G5-2*(I3+I4)/E6-G5 -> -32.5
C22: 1 | D22: =$C$3-C$4*C22 -> 80 | E22: =$C$5+$C$6*C22 -> 20 | F22: =$C$7+$C$8*C22 -> 20 | G22: =$G$5 -> 60 | H22: =$C$13+C22*$C$14 -> 13.75 | I22: =Oligo!$J$16 -> 48.936171
C23: 1.2 | D23: =$C$3-C$4*C23 -> 76 | E23: =$C$5+$C$6*C23 -> 22 | F23: =$C$7+$C$8*C23 -> 23 | G23: =$G$5 -> 60 | H23: =$C$13+C23*$C$14 -> 23 | I23: =Oligo!$J$16 -> 48.936171
C24: 1.4 | D24: =$C$3-C$4*C24 -> 72 | E24: =$C$5+$C$6*C24 -> 24 | F24: =$C$7+$C$8*C24 -> 26 | G24: =$G$5 -> 60 | H24: =$C$13+C24*$C$14 -> 32.25 | I24: =Oligo!$J$16 -> 48.936171
C25: 1.6 | D25: =$C$3-C$4*C25 -> 68 | E25: =$C$5+$C$6*C25 -> 26 | F25: =$C$7+$C$8*C25 -> 29 | G25: =$G$5 -> 60 | H25: =$C$13+C25*$C$14 -> 41.5 | I25: =Oligo!$J$16 -> 48.936171
C26: 1.8 | D26: =$C$3-C$4*C26 -> 64 | E26: =$C$5+$C$6*C26 -> 28 | F26: =$C$7+$C$8*C26 -> 32 | G26: =$G$5 -> 60 | H26: =$C$13+C26*$C$14 -> 50.75 | I26: =Oligo!$J$16 -> 48.936171
C27: 2 | D27: =$C$3-C$4*C27 -> 60 | E27: =$C$5+$C$6*C27 -> 30 | F27: =$C$7+$C$8*C27 -> 35 | G27: =$G$5 -> 60 | H27: =$C$13+C27*$C$14 -> 60 | I27: =Oligo!$J$16 -> 48.936171
C28: 2.2 | D28: =$C$3-C$4*C28 -> 56 | E28: =$C$5+$C$6*C28 -> 32 | F28: =$C$7+$C$8*C28 -> 38 | G28: =$G$5 -> 60 | H28: =$C$13+C28*$C$14 -> 69.25 | I28: =Oligo!$J$16 -> 48.936171
C29: 2.4 | D29: =$C$3-C$4*C29 -> 52 | E29: =$C$5+$C$6*C29 -> 34 | F29: =$C$7+$C$8*C29 -> 41 | G29: =$G$5 -> 60 | H29: =$C$13+C29*$C$14 -> 78.5 | I29: =Oligo!$J$16 -> 48.936171
C30: 2.6 | D30: =$C$3-C$4*C30 -> 48 | E30: =$C$5+$C$6*C30 -> 36 | F30: =$C$7+$C$8*C30 -> 44 | G30: =$G$5 -> 60 | H30: =$C$13+C30*$C$14 -> 87.75 | I30: =Oligo!$J$16 -> 48.936171
C31: 2.8 | D31: =$C$3-C$4*C31 -> 44 | E31: =$C$5+$C$6*C31 -> 38 | F31: =$C$7+$C$8*C31 -> 47 | G31: =$G$5 -> 60 | H31: =$C$13+C31*$C$14 -> 97
C32: 3 | D32: =$C$3-C$4*C32 -> 40 | E32: =$C$5+$C$6*C32 -> 40 | F32: =$C$7+$C$8*C32 -> 50 | G32: =$G$5 -> 60 | H32: =$C$13+C32*$C$14 -> 106.25
C33: 3.2 | D33: =$C$3-C$4*C33 -> 36 | E33: =$C$5+$C$6*C33 -> 42 | F33: =$C$7+$C$8*C33 -> 53 | G33: =$G$5 -> 60 | H33: =$C$13+C33*$C$14 -> 115.5
C34: 3.4 | D34: =$C$3-C$4*C34 -> 32 | E34: =$C$5+$C$6*C34 -> 44 | F34: =$C$7+$C$8*C34 -> 56 | G34: =$G$5 -> 60 | H34: =$C$13+C34*$C$14 -> 124.75
C35: 3.6 | D35: =$C$3-C$4*C35 -> 28 | E35: =$C$5+$C$6*C35 -> 46 | F35: =$C$7+$C$8*C35 -> 59 | G35: =$G$5 -> 60 | H35: =$C$13+C35*$C$14 -> 134
C36: 3.8 | D36: =$C$3-C$4*C36 -> 24 | E36: =$C$5+$C$6*C36 -> 48 | F36: =$C$7+$C$8*C36 -> 62 | G36: =$G$5 -> 60 | H36: =$C$13+C36*$C$14 -> 143.25
C37: 4 | D37: =$C$3-C$4*C37 -> 20 | E37: =$C$5+$C$6*C37 -> 50 | F37: =$C$7+$C$8*C37 -> 65 | G37: =$G$5 -> 60 | H37: =$C$13+C37*$C$14 -> 152.5
C38: 4.2 | D38: =$C$3-C$4*C38 -> 16 | E38: =$C$5+$C$6*C38 -> 52 | F38: =$C$7+$C$8*C38 -> 68 | G38: =$G$5 -> 60 | H38: =$C$13+C38*$C$14 -> 161.75
C39: 4.4 | D39: =$C$3-C$4*C39 -> 12 | E39: =$C$5+$C$6*C39 -> 54 | F39: =$C$7+$C$8*C39 -> 71 | G39: =$G$5 -> 60 | H39: =$C$13+C39*$C$14 -> 171
C40: 4.6 | D40: =$C$3-C$4*C40 -> 8 | E40: =$C$5+$C$6*C40 -> 56 | F40: =$C$7+$C$8*C40 -> 74 | G40: =$G$5 -> 60 | H40: =$C$13+C40*$C$14 -> 180.25
C41: 4.8 | D41: =$C$3-C$4*C41 -> 4 | E41: =$C$5+$C$6*C41 -> 58 | F41: =$C$7+$C$8*C41 -> 77 | G41: =$G$5 -> 60 | H41: =$C$13+C41*$C$14 -> 189.5
...

Sheet 4 Monopsonio MaxProfit 
B2: Competencia perfecta: un productor con demanda elástica
B3: Pdmx | C3: 100
B4: mD | C4: 20 | D4: Qm | E4: =E9 -> 0 | F4: Pm | G4: =C3-C4*E4 -> 100
D5: Qd | E5: =E9 -> 0
B6: PGmin | C6: 5
B7: mO | C7: 15
B8: FC | C8: 80
B9: VC | C9: =C6*E4+0.5*C7*E4^2 -> 0
B10: U | C10: =C3*E5-0.5*C4*E5*E5 -> 0
B11: CSPm | C11: =C3*E5-0.5*C4*E5^2-E5*G4 -> 0
B12: PSPm | C12: =E4*G4-(C6*E4+0.5*C7*E4*E4) -> 0
B13: SWm | C13: =C11+C12 -> 0
C15: Qg | H15: CSP
C16: 0 | H16: =$C$3*C16-0.5*$C$4*C16^2-($C$3-$C$4*C16)*C16 -> 0
C17: 0.2 | H17: =$C$3*C17-0.5*$C$4*C17^2-($C$3-$C$4*C17)*C17 -> 0.4
C18: 0.4 | H18: =$C$3*C18-0.5*$C$4*C18^2-($C$3-$C$4*C18)*C18 -> 1.6
C19: 0.6 | H19: =$C$3*C19-0.5*$C$4*C19^2-($C$3-$C$4*C19)*C19 -> 3.6
C20: 0.8 | H20: =$C$3*C20-0.5*$C$4*C20^2-($C$3-$C$4*C20)*C20 -> 6.4
C21: 1 | H21: =$C$3*C21-0.5*$C$4*C21^2-($C$3-$C$4*C21)*C21 -> 10
C22: 1.2 | H22: =$C$3*C22-0.5*$C$4*C22^2-($C$3-$C$4*C22)*C22 -> 14.4
C23: 1.4 | H23: =$C$3*C23-0.5*$C$4*C23^2-($C$3-$C$4*C23)*C23 -> 19.6
C24: 1.6 | H24: =$C$3*C24-0.5*$C$4*C24^2-($C$3-$C$4*C24)*C24 -> 25.6
C25: 1.8 | H25: =$C$3*C25-0.5*$C$4*C25^2-($C$3-$C$4*C25)*C25 -> 32.4
C26: 2 | H26: =$C$3*C26-0.5*$C$4*C26^2-($C$3-$C$4*C26)*C26 -> 40
C27: 2.2 | H27: =$C$3*C27-0.5*$C$4*C27^2-($C$3-$C$4*C27)*C27 -> 48.4
... C41: 5 | H41: =$C$3*C41-0.5*$C$4*C41^2-($C$3-$C$4*C41)*C41 -> 250

Sheet 4 Monopolio Solucion 1
B2: Competencia perfecta: un productor con demanda elástica
B3: Pdmx | C3: 100
B4: mD | C4: 20 | D4: Qr | E4: 2 | F4: Pr | G4: =C3-C4*E4 -> 60
D5: Qd | E5: =E4 -> 2 | H5: SW | I5: =SUM(C11:C12) -> 120
B6: PGmin | C6: 5 | E6: a | F6: 27.5
B7: mO | C7: 15 | E7: b | F7: -95 | G7: Qr1 | H7: =(-F7+SQRT(F7*F7-4*F6*F8))/(2*F6) -> 2
B8: FC | C8: 80 | E8: c | F8: 80 | G8: Qr2 | H8: =(-F7-SQRT(F7*F7-4*F6*F8))/(2*F6) -> 1.4545455
B9: VC | C9: =C6*E4+0.5*C7*E4^2 -> 40
B10: U | C10: =C3*E5-0.5*C4*E5*E5 -> 160
B11: CSP | C11: =C3*E5-0.5*C4*E5^2-E5*G4 -> 40
B12: PSPm | C12: =E4*G4-(C6*E4+0.5*C7*E4*E4) -> 80
B13: SWm | C13: =C11+C12 -> 120
C15: Qg | D15: Bmarg | F15: MC2 | G15: P* | H15: AC
C16: 0 | D16: =$C$3-C$4*C16 -> 100 | F16: =$C$6+$C$7*C16 -> 5 | G16: =$G$4 -> 60
C17: 0.2 | D17: =$C$3-C$4*C17 -> 96 | F17: =$C$6+$C$7*C17 -> 8 | G17: =$G$4 -> 60
C18: 0.4 | D18: =$C$3-C$4*C18 -> 92 | F18: =$C$6+$C$7*C18 -> 11 | G18: =$G$4 -> 60
C19: 0.6 | D19: =$C$3-C$4*C19 -> 88 | F19: =$C$6+$C$7*C19 -> 14 | G19: =$G$4 -> 60
C20: 0.8 | D20: =$C$3-C$4*C20 -> 84 | F20: =$C$6+$C$7*C20 -> 17 | G20: =$G$4 -> 60 | H20: =($C$8+$C$6*C20+0.5*$C$7*C20*C20)/C20 -> 111
C21: 1 | D21: =$C$3-C$4*C21 -> 80 | F21: =$C$6+$C$7*C21 -> 20 | G21: =$G$4 -> 60 | H21: =($C$8+$C$6*C21+0.5*$C$7*C21*C21)/C21 -> 92.5
C22: 1.2 | D22: =$C$3-C$4*C22 -> 76 | F22: =$C$6+$C$7*C22 -> 23 | G22: =$G$4 -> 60 | H22: =($C$8+$C$6*C22+0.5*$C$7*C22*C22)/C22 -> 80.666667
C23: 1.4 | D23: =$C$3-C$4*C23 -> 72 | F23: =$C$6+$C$7*C23 -> 26 | G23: =$G$4 -> 60 | H23: =($C$8+$C$6*C23+0.5*$C$7*C23*C23)/C23 -> 72.642857
C24: 1.6 | D24: =$C$3-C$4*C24 -> 68 | F24: =$C$6+$C$7*C24 -> 29 | G24: =$G$4 -> 60 | H24: =($C$8+$C$6*C24+0.5*$C$7*C24*C24)/C24 -> 67
C25: 1.8 | D25: =$C$3-C$4*C25 -> 64 | F25: =$C$6+$C$7*C25 -> 32 | G25: =$G$4 -> 60 | H25: =($C$8+$C$6*C25+0.5*$C$7*C25*C25)/C25 -> 62.944444
C26: 2 | D26: =$C$3-C$4*C26 -> 60 | F26: =$C$6+$C$7*C26 -> 35 | G26: =$G$4 -> 60 | H26: =($C$8+$C$6*C26+0.5*$C$7*C26*C26)/C26 -> 60
C27: 2.2 | D27: =$C$3-C$4*C27 -> 56 | F27: =$C$6+$C$7*C27 -> 38 | H27: =($C$8+$C$6*C27+0.5*$C$7*C27*C27)/C27 -> 57.863636
C28: 2.4 | D28: =$C$3-C$4*C28 -> 52 | F28: =$C$6+$C$7*C28 -> 41 | H28: =($C$8+$C$6*C28+0.5*$C$7*C28*C28)/C28 -> 56.333333
C29: 2.6 | D29: =$C$3-C$4*C29 -> 48 | F29: =$C$6+$C$7*C29 -> 44 | H29: =($C$8+$C$6*C29+0.5*$C$7*C29*C29)/C29 -> 55.269231
C30: 2.8 | D30: =$C$3-C$4*C30 -> 44 | F30: =$C$6+$C$7*C30 -> 47 | H30: =($C$8+$C$6*C30+0.5*$C$7*C30*C30)/C30 -> 54.571429
C31: 3 | D31: =$C$3-C$4*C31 -> 40 | F31: =$C$6+$C$7*C31 -> 50 | H31: =($C$8+$C$6*C31+0.5*$C$7*C31*C31)/C31 -> 54.166667
C32: 3.2 | D32: =$C$3-C$4*C32 -> 36 | F32: =$C$6+$C$7*C32 -> 53 | H32: =($C$8+$C$6*C32+0.5*$C$7*C32*C32)/C32 -> 54
C33: 3.4 | D33: =$C$3-C$4*C33 -> 32 | F33: =$C$6+$C$7*C33 -> 56 | H33: =($C$8+$C$6*C33+0.5*$C$7*C33*C33)/C33 -> 54.029412
C34: 3.6 | D34: =$C$3-C$4*C34 -> 28 | F34: =$C$6+$C$7*C34 -> 59 | H34: =($C$8+$C$6*C34+0.5*$C$7*C34*C34)/C34 -> 54.222222
C35: 3.8 | D35: =$C$3-C$4*C35 -> 24 | F35: =$C$6+$C$7*C35 -> 62 | H35: =($C$8+$C$6*C35+0.5*$C$7*C35*C35)/C35 -> 54.552632
C36: 4 | D36: =$C$3-C$4*C36 -> 20 | F36: =$C$6+$C$7*C36 -> 65 | H36: =($C$8+$C$6*C36+0.5*$C$7*C36*C36)/C36 -> 55
C37: 4.2 | D37: =$C$3-C$4*C37 -> 16 | F37: =$C$6+$C$7*C37 -> 68 | H37: =($C$8+$C$6*C37+0.5*$C$7*C37*C37)/C37 -> 55.547619
C38: 4.4 | D38: =$C$3-C$4*C38 -> 12 | F38: =$C$6+$C$7*C38 -> 71 | H38: =($C$8+$C$6*C38+0.5*$C$7*C38*C38)/C38 -> 56.181818
... C41: 5 | D41: =$C$3-C$4*C41 -> 0 | F41: =$C$6+$C$7*C41 -> 80 | H41: =($C$8+$C$6*C41+0.5*$C$7*C41*C41)/C41 -> 58.5

Sheet 4 Monopolio Solucion 2
B2: Competencia perfecta: un productor con demanda elástica
B3: Pdmx | C3: 100
B4: mD | C4: 20 | D4: Qr | E4: =H8 -> 1.4545455 | F4: Pr | G4: =C3-C4*E4 -> 70.909091
D5: Qd | E5: =E4 -> 1.4545455 | H5: SW | I5: =SUM(C11:C12) -> 101.15702
B6: PGmin | C6: 5 | E6: a | F6: 27.5
B7: mO | C7: 15 | E7: b | F7: -95 | G7: Qr1 | H7: =(-F7+SQRT(F7*F7-4*F6*F8))/(2*F6) -> 2
B8: FC | C8: 80 | E8: c | F8: 80 | G8: Qr2 | H8: =(-F7-SQRT(F7*F7-4*F6*F8))/(2*F6) -> 1.4545455
B9: VC | C9: =C6*E4+0.5*C7*E4^2 -> 23.140496
B10: U | C10: =C3*E5-0.5*C4*E5*E5 -> 124.29752
B11: CSP | C11: =C3*E5-0.5*C4*E5^2-E5*G4 -> 21.157025
B12: PSPm | C12: =E4*G4-(C6*E4+0.5*C7*E4*E4) -> 80
B13: SWm | C13: =C11+C12 -> 101.15702
C15: Qg | D15: Bmarg | F15: MC2 | G15: P* | H15: AC
C16: 0 | D16: =$C$3-C$4*C16 -> 100 | F16: =$C$6+$C$7*C16 -> 5 | G16: =$G$4 -> 70.909091
C17: 0.2 | D17: =$C$3-C$4*C17 -> 96 | F17: =$C$6+$C$7*C17 -> 8 | G17: =$G$4 -> 70.909091
C18: 0.4 | D18: =$C$3-C$4*C18 -> 92 | F18: =$C$6+$C$7*C18 -> 11 | G18: =$G$4 -> 70.909091
C19: 0.6 | D19: =$C$3-C$4*C19 -> 88 | F19: =$C$6+$C$7*C19 -> 14 | G19: =$G$4 -> 70.909091
C20: 0.8 | D20: =$C$3-C$4*C20 -> 84 | F20: =$C$6+$C$7*C20 -> 17 | G20: =$G$4 -> 70.909091 | H20: =($C$8+$C$6*C20+0.5*$C$7*C20*C20)/C20 -> 111
C21: 1 | D21: =$C$3-C$4*C21 -> 80 | F21: =$C$6+$C$7*C21 -> 20 | G21: =$G$4 -> 70.909091 | H21: =($C$8+$C$6*C21+0.5*$C$7*C21*C21)/C21 -> 92.5
C22: 1.2 | D22: =$C$3-C$4*C22 -> 76 | F22: =$C$6+$C$7*C22 -> 23 | G22: =$G$4 -> 70.909091 | H22: =($C$8+$C$6*C22+0.5*$C$7*C22*C22)/C22 -> 80.666667
C23: 1.4 | D23: =$C$3-C$4*C23 -> 72 | F23: =$C$6+$C$7*C23 -> 26 | G23: =$G$4 -> 70.909091 | H23: =($C$8+$C$6*C23+0.5*$C$7*C23*C23)/C23 -> 72.642857
C24: 1.6 | D24: =$C$3-C$4*C24 -> 68 | F24: =$C$6+$C$7*C24 -> 29 | H24: =($C$8+$C$6*C24+0.5*$C$7*C24*C24)/C24 -> 67
C25: 1.8 | D25: =$C$3-C$4*C25 -> 64 | F25: =$C$6+$C$7*C25 -> 32 | H25: =($C$8+$C$6*C25+0.5*$C$7*C25*C25)/C25 -> 62.944444
C26: 2 | D26: =$C$3-C$4*C26 -> 60 | F26: =$C$6+$C$7*C26 -> 35 | H26: =($C$8+$C$6*C26+0.5*$C$7*C26*C26)/C26 -> 60
C27: 2.2 | D27: =$C$3-C$4*C27 -> 56 | F27: =$C$6+$C$7*C27 -> 38 | H27: =($C$8+$C$6*C27+0.5*$C$7*C27*C27)/C27 -> 57.863636
C28: 2.4 | D28: =$C$3-C$4*C28 -> 52 | F28: =$C$6+$C$7*C28 -> 41 | H28: =($C$8+$C$6*C28+0.5*$C$7*C28*C28)/C28 -> 56.333333
C29: 2.6 | D29: =$C$3-C$4*C29 -> 48 | F29: =$C$6+$C$7*C29 -> 44 | H29: =($C$8+$C$6*C29+0.5*$C$7*C29*C29)/C29 -> 55.269231
C30: 2.8 | D30: =$C$3-C$4*C30 -> 44 | F30: =$C$6+$C$7*C30 -> 47 | H30: =($C$8+$C$6*C30+0.5*$C$7*C30*C30)/C30 -> 54.571429
C31: 3 | D31: =$C$3-C$4*C31 -> 40 | F31: =$C$6+$C$7*C31 -> 50 | H31: =($C$8+$C$6*C31+0.5*$C$7*C31*C31)/C31 -> 54.166667
C32: 3.2 | D32: =$C$3-C$4*C32 -> 36 | F32: =$C$6+$C$7*C32 -> 53 | H32: =($C$8+$C$6*C32+0.5*$C$7*C32*C32)/C32 -> 54
C33: 3.4 | D33: =$C$3-C$4*C33 -> 32 | F33: =$C$6+$C$7*C33 -> 56 | H33: =($C$8+$C$6*C33+0.5*$C$7*C33*C33)/C33 -> 54.029412
C34: 3.6 | D34: =$C$3-C$4*C34 -> 28 | F34: =$C$6+$C$7*C34 -> 59 | H34: =($C$8+$C$6*C34+0.5*$C$7*C34*C34)/C34 -> 54.222222
C35: 3.8 | D35: =$C$3-C$4*C35 -> 24 | F35: =$C$6+$C$7*C35 -> 62 | H35: =($C$8+$C$6*C35+0.5*$C$7*C35*C35)/C35 -> 54.552632
... C41: 5 | D41: =$C$3-C$4*C41 -> 0 | F41: =$C$6+$C$7*C41 -> 80 | H41: =($C$8+$C$6*C41+0.5*$C$7*C41*C41)/C41 -> 58.5

Sheet 4 Monopolio MaxProfit
B2: Competencia perfecta: un productor con demanda elástica
B3: Pdmx | C3: 100
B4: mD | C4: 20 | D4: Qm | E4: 1.7272727 | F4: Pm | G4: =C3-C4*E4 -> 65.454545
D5: Qd | E5: 1.7272727
B6: PGmin | C6: 5
B7: mO | C7: 15
B8: FC | C8: 80
B9: VC | C9: =C6*E4+0.5*C7*E4^2 -> 31.012397 | E9: =(C3-C6)/(2*C4+C7) -> 1.7272727
B10: U | C10: =C3*E5-0.5*C4*E5*E5 -> 142.89256
B11: CSPm | C11: =C3*E5-0.5*C4*E5^2-E5*G4 -> 29.834711
B12: PSPm | C12: =E4*G4-(C6*E4+0.5*C7*E4*E4) -> 82.045455
B13: SWm | C13: =C11+C12 -> 111.88017
C15: Qg | D15: Bmarg | F15: MC2 | G15: P* | H15: MR
C16: 0 | D16: =$C$3-C$4*C16 -> 100 | F16: =$C$6+$C$7*C16 -> 5 | G16: =$G$4 -> 65.454545
C17: 0.2 | D17: =$C$3-C$4*C17 -> 96 | F17: =$C$6+$C$7*C17 -> 8 | G17: =$G$4 -> 65.454545
C18: 0.4 | D18: =$C$3-C$4*C18 -> 92 | F18: =$C$6+$C$7*C18 -> 11 | G18: =$G$4 -> 65.454545
C19: 0.6 | D19: =$C$3-C$4*C19 -> 88 | F19: =$C$6+$C$7*C19 -> 14 | G19: =$G$4 -> 65.454545
C20: 0.8 | D20: =$C$3-C$4*C20 -> 84 | F20: =$C$6+$C$7*C20 -> 17 | G20: =$G$4 -> 65.454545
C21: 1 | D21: =$C$3-C$4*C21 -> 80 | F21: =$C$6+$C$7*C21 -> 20 | G21: =$G$4 -> 65.454545
C22: 1.2 | D22: =$C$3-C$4*C22 -> 76 | F22: =$C$6+$C$7*C22 -> 23 | G22: =$G$4 -> 65.454545
C23: 1.4 | D23: =$C$3-C$4*C23 -> 72 | F23: =$C$6+$C$7*C23 -> 26 | G23: =$G$4 -> 65.454545 | H23: =-$C$4*C23+$C$3-$C$4*C23 -> 44
C24: 1.6 | D24: =$C$3-C$4*C24 -> 68 | F24: =$C$6+$C$7*C24 -> 29 | G24: =$G$4 -> 65.454545 | H24: =-$C$4*C24+$C$3-$C$4*C24 -> 36
C25: 1.8 | D25: =$C$3-C$4*C25 -> 64 | F25: =$C$6+$C$7*C25 -> 32 | G25: =$G$4 -> 65.454545 | H25: =-$C$4*C25+$C$3-$C$4*C25 -> 28
C26: 2 | D26: =$C$3-C$4*C26 -> 60 | F26: =$C$6+$C$7*C26 -> 35 | G26: =$G$4 -> 65.454545 | H26: =-$C$4*C26+$C$3-$C$4*C26 -> 20
C27: 2.2 | D27: =$C$3-C$4*C27 -> 56 | F27: =$C$6+$C$7*C27 -> 38 | G27: =$G$4 -> 65.454545 | H27: =-$C$4*C27+$C$3-$C$4*C27 -> 12
C28: 2.4 | D28: =$C$3-C$4*C28 -> 52 | F28: =$C$6+$C$7*C28 -> 41 | H28: =-$C$4*C28+$C$3-$C$4*C28 -> 4
C29: 2.6 | D29: =$C$3-C$4*C29 -> 48 | F29: =$C$6+$C$7*C29 -> 44
C30: 2.8 | D30: =$C$3-C$4*C30 -> 44 | F30: =$C$6+$C$7*C30 -> 47
C31: 3 | D31: =$C$3-C$4*C31 -> 40 | F31: =$C$6+$C$7*C31 -> 50
C32: 3.2 | D32: =$C$3-C$4*C32 -> 36 | F32: =$C$6+$C$7*C32 -> 53
C33: 3.4 | D33: =$C$3-C$4*C33 -> 32 | F33: =$C$6+$C$7*C33 -> 56
C34: 3.6 | D34: =$C$3-C$4*C34 -> 28 | F34: =$C$6+$C$7*C34 -> 59
C35: 3.8 | D35: =$C$3-C$4*C35 -> 24 | F35: =$C$6+$C$7*C35 -> 62
C36: 4 | D36: =$C$3-C$4*C36 -> 20 | F36: =$C$6+$C$7*C36 -> 65
C37: 4.2 | D37: =$C$3-C$4*C37 -> 16 | F37: =$C$6+$C$7*C37 -> 68
C38: 4.4 | D38: =$C$3-C$4*C38 -> 12 | F38: =$C$6+$C$7*C38 -> 71
C39: 4.6 | D39: =$C$3-C$4*C39 -> 8 | F39: =$C$6+$C$7*C39 -> 74
C40: 4.8 | D40: =$C$3-C$4*C40 -> 4 | F40: =$C$6+$C$7*C40 -> 77
C41: 5 | D41: =$C$3-C$4*C41 -> 0 | F41: =$C$6+$C$7*C41 -> 80

Sheet Informe de respuestas 1
A1: Microsoft Excel 14.1 Informe de respuestas
A2: Hoja de cálculo: [1 generador sin red elastico.xlsx]2 CPerf 1 generador solver
A3: Informe creado: 7/30/2017 19:08:22
A4: Resultado: Solver encontró una solución. Se cumplen todas las restricciones y condiciones óptimas.
A5: Motor de Solver
B6: Motor: GRG Nonlinear
B7: Tiempo de la solución: 0.661672 segundos.
B8: Iteraciones: 1 Subproblemas: 0
A9: Opciones de Solver
B10: Tiempo máximo Ilimitado, Iteraciones Ilimitado, Precision 0.000001
B11: Convergencia 0.0001, Tamaño de población 100, Valor de inicialización aleatorio 0, Adelantada de derivados, Requerir límites
B12: Máximo de subproblemas Ilimitado, Máximo de soluciones de enteros Ilimitado, Tolerancia de enteros 1%, Resolver sin restricciones de enteros, Asumir no negativo
A14: Celda objetivo (Máx.)
B15: Celda | C15: Nombre | D15: Valor original | E15: Valor final
B16: $C$13 | C16: SW | D16: 128.92857 | E16: 128.92857
A19: Celdas de variables
B20: Celda | C20: Nombre | D20: Valor original | E20: Valor final | F20: Entero
B21: $E$4 | C21: Q* | D21: 2.7142857 | E21: 2.7142857 | F21: Continuar
A24: Restricciones
B25: Celda | C25: Nombre | D25: Valor de la celda | E25: Fórmula | F25: Estado | G25: Demora
B26: $F$11 | C26: Q2 P* | D26: 2.7142857 | E26: $F$11=F12C6 | F26: Vinculante | G26: 0

Sheet Informe de límites 1
A1: Microsoft Excel 14.1 Informe de límites
A2: Hoja de cálculo: [1 generador sin red elastico.xlsx]2 CPerf 1 generador solver
A3: Informe creado: 7/30/2017 19:08:25
C6: Objetivo
B7: Celda | C7: Nombre | D7: Valor
B8: $E$4 | C8: Q* | D8: 0
C11: Variable | F11: Inferior | G11: Objetivo | I11: Superior | J11: Objetivo
B12: Celda | C12: Nombre | D12: Valor | F12: Límite | G12: Resultado | I12: Límite | J12: Resultado
B13: $E$4 | C13: Q* | D13: 2.7142857 | F13: 0 | G13: 0 | I13: #N/A | J13: #N/A

Sheet Informe de límites 2
A1: Microsoft Excel 14.1 Informe de límites
A2: Hoja de cálculo: [1 generador sin red elastico.xlsx]2 CPerf 1 generador solver
A3: Informe creado: 7/30/2017 19:12:47
C6: Objetivo
B7: Celda | C7: Nombre | D7: Valor
B8: $E$5 | C8: Qd | D8: 0
C11: Variable | F11: Inferior | G11: Objetivo | I11: Superior | J11: Objetivo
B12: Celda | C12: Nombre | D12: Valor | F12: Límite | G12: Resultado | I12: Límite | J12: Resultado
B13: $E$5 | C13: Qd | D13: 2.7142857 | F13: 2.7142857 | G13: 128.92857 | I13: 2.7142857 | J13: 128.92857

Sheet Informe de confidencialidad 1
A1: Microsoft Excel 14.1 Informe de confidencialidad
A2: Hoja de cálculo: [1 generador sin red elastico.xlsx]2 CPerf 1 generador solver
A3: Informe creado: 7/30/2017 19:08:22
E4: 53687091
A6: Celdas de variables
D7: Final | E7: Reducido
B8: Celda | C8: Nombre | D8: Valor | E8: Degradado
B9: $E$4 | C9: Q* | D9: 2.7142857 | E9: 0
A11: Restricciones
D12: Final | E12: Lagrange
B13: Celda | C13: Nombre | D13: Valor | E13: Multiplicador
B14: $F$11 | C14: Q2 P* | D14: 2.7142857 | E14: 0

Sheet Informe de respuestas 2
A1: Microsoft Excel 14.1 Informe de respuestas
A2: Hoja de cálculo: [1 generador sin red elastico.xlsx]2 CPerf 1 generador solver
A3: Informe creado: 7/30/2017 19:12:44
A4: Resultado: Solver encontró una solución. Se cumplen todas las restricciones y condiciones óptimas.
A5: Motor de Solver
B6: Motor: GRG Nonlinear
B7: Tiempo de la solución: 0.522274 segundos.
B8: Iteraciones: 2 Subproblemas: 0
A9: Opciones de Solver
B10: Tiempo máximo Ilimitado, Iteraciones Ilimitado, Precision 0.000001
B11: Convergencia 0.0001, Tamaño de población 100, Valor de inicialización aleatorio 0, Adelantada de derivados, Requerir límites
B12: Máximo de subproblemas Ilimitado, Máximo de soluciones de enteros Ilimitado, Tolerancia de enteros 1%, Resolver sin restricciones de enteros, Asumir no negativo
A14: Celda objetivo (Máx.)
B15: Celda | C15: Nombre | D15: Valor original | E15: Valor final
B16: $C$13 | C16: SW | D16: 0 | E16: 128.92857
A19: Celdas de variables
B20: Celda | C20: Nombre | D20: Valor original | E20: Valor final | F20: Entero
B21: $E$4 | C21: Q* | D21: 0 | E21: 2.7142857 | F21: Continuar
B22: $E$5 | C22: Qd | D22: 0 | E22: 2.7142857 | F22: Continuar
A25: Restricciones
B26: Celda | C26: Nombre | D26: Valor de la celda | E26: Fórmula | F26: Estado | G26: Demora
B27: $E$5 | C27: Qd | D27: 2.7142857 | E27: $E$5=F4C5 | F27: Vinculante | G27: 0

Sheet Informe de confidencialidad 2
A1: Microsoft Excel 14.1 Informe de confidencialidad
A2: Hoja de cálculo: [1 generador sin red elastico.xlsx]2 CPerf 1 generador solver
A3: Informe creado: 7/30/2017 19:12:44
A6: Celdas de variables
D7: Final | E7: Reducido
B8: Celda | C8: Nombre | D8: Valor | E8: Degradado
B9: $E$4 | C9: Q* | D9: 2.7142857 | E9: 0
B10: $E$5 | C10: Qd | D10: 2.7142857 | E10: 0
A12: Restricciones
D13: Final | E13: Lagrange
B14: Celda | C14: Nombre | D14: Valor | E14: Multiplicador
B15: $E$5 | C15: Qd | D15: 2.7142857 | E15: 45.714249
J21: =1-100/(20*2.7) -> -0.85185185

Sheet 2 CPerf 1 generador solver
B2: Competencia perfecta: un productor con demanda elástica
B3: Pdmx | C3: 100
B4: mD | C4: 20 | D4: Q* | E4: 2.7142857 | F4: P* | G4: =C3-C4*E4 -> 45.714286
D5: Qd | E5: 2.7142857 | H5: SW | I5: =SUM(C11:C12) -> 128.92857
B6: PGmin | C6: 5
B7: mO | C7: 15
B8: FC | C8: 80
B9: VC | C9: =C6*E4+0.5*C7*E4^2+C8 -> 148.82653 | E9: Multiplicador de Lagrange
B10: U | C10: =C3*E5-0.5*C4*E5*E5 -> 197.7551 | E10: l | F10: =G4 -> 45.714286
B11: CSP | C11: =C3*E5-0.5*C4*E5^2-E5*G4 -> 73.673469 | E11: Q2 | F11: =E4 -> 2.7142857 | G11: =C3-C4*F12-F10 -> 0
B12: PSP | C12: =E4*G4-(C6*E4+0.5*C7*E4*E4) -> 55.255102 | E12: QD | F12: =E5 -> 2.7142857 | G12: =F12-F11 -> 0
B13: SW | C13: =C11+C12 -> 128.92857
C15: Qg | D15: Bmarg | F15: MC2 | G15: P*
C16: 0 | D16: =$C$3-C$4*C16 -> 100 | F16: =$C$6+$C$7*C16 -> 5 | G16: =$G$4 -> 45.714286
C17: 0.2 | D17: =$C$3-C$4*C17 -> 96 | F17: =$C$6+$C$7*C17 -> 8 | G17: =$G$4 -> 45.714286
C18: 0.4 | D18: =$C$3-C$4*C18 -> 92 | F18: =$C$6+$C$7*C18 -> 11 | G18: =$G$4 -> 45.714286
C19: 0.6 | D19: =$C$3-C$4*C19 -> 88 | F19: =$C$6+$C$7*C19 -> 14 | G19: =$G$4 -> 45.714286
C20: 0.8 | D20: =$C$3-C$4*C20 -> 84 | F20: =$C$6+$C$7*C20 -> 17 | G20: =$G$4 -> 45.714286
C21: 1 | D21: =$C$3-C$4*C21 -> 80 | F21: =$C$6+$C$7*C21 -> 20 | G21: =$G$4 -> 45.714286
C22: 1.2 | D22: =$C$3-C$4*C22 -> 76 | F22: =$C$6+$C$7*C22 -> 23 | G22: =$G$4 -> 45.714286
C23: 1.4 | D23: =$C$3-C$4*C23 -> 72 | F23: =$C$6+$C$7*C23 -> 26 | G23: =$G$4 -> 45.714286
C24: 1.6 | D24: =$C$3-C$4*C24 -> 68 | F24: =$C$6+$C$7*C24 -> 29 | G24: =$G$4 -> 45.714286
C25: 1.8 | D25: =$C$3-C$4*C25 -> 64 | F25: =$C$6+$C$7*C25 -> 32 | G25: =$G$4 -> 45.714286
C26: 2 | D26: =$C$3-C$4*C26 -> 60 | F26: =$C$6+$C$7*C26 -> 35 | G26: =$G$4 -> 45.714286
C27: 2.2 | D27: =$C$3-C$4*C27 -> 56 | F27: =$C$6+$C$7*C27 -> 38 | G27: =$G$4 -> 45.714286
... C29: 2.6 | D29: =$C$3-C$4*C29 -> 48 | F29: =$C$6+$C$7*C29 -> 44 | G29: =$G$4 -> 45.714286
C30: 2.8 | D30: =$C$3-C$4*C30 -> 44 | F30: =$C$6+$C$7*C30 -> 47
C31: 3 | D31: =$C$3-C$4*C31 -> 40 | F31: =$C$6+$C$7*C31 -> 50
C32: 3.2 | D32: =$C$3-C$4*C32 -> 36 | F32: =$C$6+$C$7*C32 -> 53
C33: 3.4 | D33: =$C$3-C$4*C33 -> 32 | F33: =$C$6+$C$7*C33 -> 56
C34: 3.6 | D34: =$C$3-C$4*C34 -> 28 | F34: =$C$6+$C$7*C34 -> 59
C35: 3.8 | D35: =$C$3-C$4*C35 -> 24 | F35: =$C$6+$C$7*C35 -> 62
C36: 4 | D36: =$C$3-C$4*C36 -> 20 | F36: =$C$6+$C$7*C36 -> 65
C37: 4.2 | D37: =$C$3-C$4*C37 -> 16 | F37: =$C$6+$C$7*C37 -> 68
C38: 4.4 | D38: =$C$3-C$4*C38 -> 12 | F38: =$C$6+$C$7*C38 -> 71
C39: 4.6 | D39: =$C$3-C$4*C39 -> 8 | F39: =$C$6+$C$7*C39 -> 74
C40: 4.8 | D40: =$C$3-C$4*C40 -> 4 | F40: =$C$6+$C$7*C40 -> 77
C41: 5 | D41: =$C$3-C$4*C41 -> 0 | F41: =$C$6+$C$7*C41 -> 80

Sheet 1 Costos
B2: Competencia perfecta
B5: PG1min | C5: 5
B6: mO1 | C6: 15
C8: Q | D8: FC | E8: VC | F8: TC | G8: AC | H8: MC | I8: Bmarg
C11: 0.4 | D11: 80 | E11: =$C$5*C11+0.5*$C$6*C11^2 -> 3.2 | F11: =D11+E11 -> 83.2 | G11: =F11/C11 -> 208 | H11: =$C$5+$C$6*C11 -> 11 | I11: =100-20*C11 -> 92 | J11: =I11-G11 -> -116
C12: 0.6 | D12: 80 | E12: =$C$5*C12+0.5*$C$6*C12^2 -> 5.7 | F12: =D12+E12 -> 85.7 | G12: =F12/C12 -> 142.83333 | H12: =$C$5+$C$6*C12 -> 14 | I12: =100-20*C12 -> 88 | J12: =I12-G12 -> -54.833333
C13: 0.8 | D13: 80 | E13: =$C$5*C13+0.5*$C$6*C13^2 -> 8.8 | F13: =D13+E13 -> 88.8 | G13: =F13/C13 -> 111 | H13: =$C$5+$C$6*C13 -> 17 | I13: =100-20*C13 -> 84 | J13: =I13-G13 -> -27
C14: 1 | D14: 80 | E14: =$C$5*C14+0.5*$C$6*C14^2 -> 12.5 | F14: =D14+E14 -> 92.5 | G14: =F14/C14 -> 92.5 | H14: =$C$5+$C$6*C14 -> 20 | I14: =100-20*C14 -> 80 | J14: =I14-G14 -> -12.5
C15: 1.2 | D15: 80 | E15: =$C$5*C15+0.5*$C$6*C15^2 -> 16.8 | F15: =D15+E15 -> 96.8 | G15: =F15/C15 -> 80.666667 | H15: =$C$5+$C$6*C15 -> 23 | I15: =100-20*C15 -> 76 | J15: =I15-G15 -> -4.6666667
C16: 1.4 | D16: 80 | E16: =$C$5*C16+0.5*$C$6*C16^2 -> 21.7 | F16: =D16+E16 -> 101.7 | G16: =F16/C16 -> 72.642857 | H16: =$C$5+$C$6*C16 -> 26 | I16: =100-20*C16 -> 72 | J16: =I16-G16 -> -0.64285714
C17: 1.6 | D17: 80 | E17: =$C$5*C17+0.5*$C$6*C17^2 -> 27.2 | F17: =D17+E17 -> 107.2 | G17: =F17/C17 -> 67 | H17: =$C$5+$C$6*C17 -> 29 | I17: =100-20*C17 -> 68 | J17: =I17-G17 -> 1
C18: 1.8 | D18: 80 | E18: =$C$5*C18+0.5*$C$6*C18^2 -> 33.3 | F18: =D18+E18 -> 113.3 | G18: =F18/C18 -> 62.944444 | H18: =$C$5+$C$6*C18 -> 32 | I18: =100-20*C18 -> 64 | J18: =I18-G18 -> 1.0555556
C19: 2 | D19: 80 | E19: =$C$5*C19+0.5*$C$6*C19^2 -> 40 | F19: =D19+E19 -> 120 | G19: =F19/C19 -> 60 | H19: =$C$5+$C$6*C19 -> 35 | I19: =100-20*C19 -> 60 | J19: =I19-G19 -> 0
C20: 2.2 | D20: 80 | E20: =$C$5*C20+0.5*$C$6*C20^2 -> 47.3 | F20: =D20+E20 -> 127.3 | G20: =F20/C20 -> 57.863636 | H20: =$C$5+$C$6*C20 -> 38 | I20: =100-20*C20 -> 56 | J20: =I20-G20 -> -1.8636364
C21: 2.4 | D21: 80 | E21: =$C$5*C21+0.5*$C$6*C21^2 -> 55.2 | F21: =D21+E21 -> 135.2 | G21: =F21/C21 -> 56.333333 | H21: =$C$5+$C$6*C21 -> 41 | I21: =100-20*C21 -> 52 | J21: =I21-G21 -> -4.3333333
C22: 2.6 | D22: 80 | E22: =$C$5*C22+0.5*$C$6*C22^2 -> 63.7 | F22: =D22+E22 -> 143.7 | G22: =F22/C22 -> 55.269231 | H22: =$C$5+$C$6*C22 -> 44 | I22: =100-20*C22 -> 48 | J22: =I22-G22 -> -7.2692308
... C34: 5 | D34: 80 | E34: =$C$5*C34+0.5*$C$6*C34^2 -> 212.5 | F34: =D34+E34 -> 292.5 | G34: =F34/C34 -> 58.5 | H34: =$C$5+$C$6*C34 -> 80 | I34: =100-20*C34 -> 0 | J34: =I34-G34 -> -58.5
G35: =59*2.8 -> 165.2 | H35: =H23*2.8 -> 131.6 | I35: =H35-G35 -> -33.6

Sheet CPerf CON restriciones (2)
H1: Competencia perfecta | L1: Oligopolio
B2: Competencia perfecta | H2: CSP | I2: =C3*E6-0.5*C4*E6^2-E6*G5 -> 118.53261 | L2: CSP | M2: =C3*E7-0.5*C4*E7^2-E7*G6 -> 65.187865
B3: PDMX | C3: 100 | D3: Qg1 | E3: 1.7 | F3: 1.7 | H3: PSP1 | I3: =E3*G5-(C5*E3+0.5*C6*E3*E3) -> 21.492876 | L3: PSP1 | M3: =G7*G6-(C6*G7+0.5*C6*G7*G7) -> 42.111817
B4: mD | C4: 20 | D4: Qg2 | E4: 1.7428566 | F4: 5 | H4: PSP2 | I4: =E4*G5-(C7*E4+0.5*C8*E4*E4) -> 22.781652 | J4: beta= | K4: =J5*2/E6 -> 25.719647 | L4: PSP2 | M4: =G8*G6-(C7*G8+0.5*C8*G8*G8) -> 43.335221
B5: PG1min | C5: 10 | E5: =SUM(E3:E4) -> 3.4428566 | F5: P* | G5: =C3-C4*E6 -> 31.142868 | H5: SW | I5: =SUM(I2:I4) -> 162.80714 | J5: =SUM(I3:I4) -> 44.274528 | L5: SW | M5: =SUM(M2:M4) -> 150.6349
B6: mO1 | C6: 10 | D6: Qd | E6: 3.4428566 | F6: Pm | G6: =Oligo!J16 -> 48.936171
B7: PG2min | C7: 5 | D7: Qm | E7: =G7+G8 -> 2.5531915 | F7: Qm1 | G7: =Oligo!J17 -> 1.2978723 | J7: Perdida de eficiencia | M7: =I5-M5 -> 12.17224
B8: mO2 | C8: 15 | F8: Qm2 | G8: =Oligo!J18 -> 1.2553191
B9: TC1 | C9: =C5*E3+0.5*C6*E3^2 -> 31.45
B10: TC2 | C10: =C7*E4+0.5*C8*E4^2 -> 31.495901
B11: U | C11: =C3*E6-0.5*C4*E6*E6 -> 225.75304
B12: SW | C12: =C11-C9-C10 -> 162.80714 | K12: Multiplicador de Lagrange
B13: Pgmin eq | C13: =G5-K4 -> 5.4232213 | M13: =C5+C6*L14-L17-L18 -> 8.7589287e-05
B14: mOeq | C14: =K4/E6 -> 7.4704381 | K14: Q1 | L14: 1.7 | M14: =C7+C8*L15-L17+L19 -> 8.7589287e-05
K15: Q2 | L15: 1.7428566 | M15: =C3-C4*L16-L17 -> 8.7589287e-05
C16: Qg | D16: Bmarg | E16: MC1 | F16: MC2 | G16: P* | H16: eq | I16: Pm | K16: QD | L16: 3.4428566 | M16: =L16-L15-L14 -> 0
C17: 0 | D17: =$C$3-C$4*C17 -> 100 | E17: =$C$5+$C$6*C17 -> 10 | F17: =$C$7+$C$8*C17 -> 5 | G17: =$G$5 -> 31.142868 | H17: =$C$13+C17*$C$14 -> 5.4232213 | I17: =Oligo!$J$16 -> 48.936171 | K17: l | L17: =26.9999806249993+4.1428 -> 31.142781 | M17: =L14-F3+L21 -> 0
C18: 0.2 | D18: =$C$3-C$4*C18 -> 96 | E18: =$C$5+$C$6*C18 -> 12 | F18: =$C$7+$C$8*C18 -> 8 | G18: =$G$5 -> 31.142868 | H18: =$C$13+C18*$C$14 -> 6.9173089 | I18: =Oligo!$J$16 -> 48.936171 | K18: m1 | L18: -4.1428682 | M18: =L15-F4+L20 -> 0
C19: 0.4 | D19: =$C$3-C$4*C19 -> 92 | E19: =$C$5+$C$6*C19 -> 14 | F19: =$C$7+$C$8*C19 -> 11 | G19: =$G$5 -> 31.142868 | H19: =$C$13+C19*$C$14 -> 8.4113965 | I19: =Oligo!$J$16 -> 48.936171 | K19: m2 | L19: 1.9375001e-05 | M19: =L18*(L14-F3) -> 0
C20: 0.6 | D20: =$C$3-C$4*C20 -> 88 | E20: =$C$5+$C$6*C20 -> 16 | F20: =$C$7+$C$8*C20 -> 14 | G20: =$G$5 -> 31.142868 | H20: =$C$13+C20*$C$14 -> 9.9054841 | I20: =Oligo!$J$16 -> 48.936171 | K20: b2 | L20: 3.2571434 | M20: =L19*(L14-F4) -> -6.3937502e-05
C21: 0.8 | D21: =$C$3-C$4*C21 -> 84 | E21: =$C$5+$C$6*C21 -> 18 | F21: =$C$7+$C$8*C21 -> 17 | G21: =$G$5 -> 31.142868 | H21: =$C$13+C21*$C$14 -> 11.399572 | I21: =Oligo!$J$16 -> 48.936171 | K21: b1 | L21: 0
C22: 1 | D22: =$C$3-C$4*C22 -> 80 | E22: =$C$5+$C$6*C22 -> 20 | F22: =$C$7+$C$8*C22 -> 20 | G22: =$G$5 -> 31.142868 | H22: =$C$13+C22*$C$14 -> 12.893659 | I22: =Oligo!$J$16 -> 48.936171
C23: 1.2 | D23: =$C$3-C$4*C23 -> 76 | E23: =$C$5+$C$6*C23 -> 22 | F23: =$C$7+$C$8*C23 -> 23 | G23: =$G$5 -> 31.142868 | H23: =$C$13+C23*$C$14 -> 14.387747 | I23: =Oligo!$J$16 -> 48.936171
C24: 1.4 | D24: =$C$3-C$4*C24 -> 72 | E24: =$C$5+$C$6*C24 -> 24 | F24: =$C$7+$C$8*C24 -> 26 | G24: =$G$5 -> 31.142868 | H24: =$C$13+C24*$C$14 -> 15.881835 | I24: =Oligo!$J$16 -> 48.936171 | K24: P* | L24: =L17+L18 -> 26.999912 | M24: = | N24: =L17 -> 31.142781 | O24: + | P24: =L18 -> -4.1428682
C25: 1.6 | D25: =$C$3-C$4*C25 -> 68 | E25: =$C$5+$C$6*C25 -> 26 | F25: =$C$7+$C$8*C25 -> 29 | G25: =$G$5 -> 31.142868 | H25: =$C$13+C25*$C$14 -> 17.375922 | I25: =Oligo!$J$16 -> 48.936171
C26: 1.8 | D26: =$C$3-C$4*C26 -> 64 | E26: =$C$5+$C$6*C26 -> 28 | F26: =$C$7+$C$8*C26 -> 32 | G26: =$G$5 -> 31.142868 | H26: =$C$13+C26*$C$14 -> 18.87001 | I26: =Oligo!$J$16 -> 48.936171
C27: 2 | D27: =$C$3-C$4*C27 -> 60 | E27: =$C$5+$C$6*C27 -> 30 | F27: =$C$7+$C$8*C27 -> 35 | G27: =$G$5 -> 31.142868 | H27: =$C$13+C27*$C$14 -> 20.364097 | I27: =Oligo!$J$16 -> 48.936171 | K27: Cmg1 | L27: =L17+L21 -> 31.142781
C28: 2.2 | D28: =$C$3-C$4*C28 -> 56 | E28: =$C$5+$C$6*C28 -> 32 | F28: =$C$7+$C$8*C28 -> 38 | G28: =$G$5 -> 31.142868 | H28: =$C$13+C28*$C$14 -> 21.858185 | I28: =Oligo!$J$16 -> 48.936171 | K28: Cmg2 | L28: =L17+L20 -> 34.399924
C29: 2.4 | D29: =$C$3-C$4*C29 -> 52 | E29: =$C$5+$C$6*C29 -> 34 | F29: =$C$7+$C$8*C29 -> 41 | G29: =$G$5 -> 31.142868 | H29: =$C$13+C29*$C$14 -> 23.352273 | I29: =Oligo!$J$16 -> 48.936171
C30: 2.6 | D30: =$C$3-C$4*C30 -> 48 | E30: =$C$5+$C$6*C30 -> 36 | F30: =$C$7+$C$8*C30 -> 44 | G30: =$G$5 -> 31.142868 | H30: =$C$13+C30*$C$14 -> 24.84636 | I30: =Oligo!$J$16 -> 48.936171
C31: 2.8 | D31: =$C$3-C$4*C31 -> 44 | E31: =$C$5+$C$6*C31 -> 38 | F31: =$C$7+$C$8*C31 -> 47 | G31: =$G$5 -> 31.142868 | H31: =$C$13+C31*$C$14 -> 26.340448
C32: 3 | D32: =$C$3-C$4*C32 -> 40 | E32: =$C$5+$C$6*C32 -> 40 | F32: =$C$7+$C$8*C32 -> 50 | G32: =$G$5 -> 31.142868 | H32: =$C$13+C32*$C$14 -> 27.834535
C33: 3.2 | D33: =$C$3-C$4*C33 -> 36 | E33: =$C$5+$C$6*C33 -> 42 | F33: =$C$7+$C$8*C33 -> 53 | G33: =$G$5 -> 31.142868 | H33: =$C$13+C33*$C$14 -> 29.328623
C34: 3.4 | D34: =$C$3-C$4*C34 -> 32 | E34: =$C$5+$C$6*C34 -> 44 | F34: =$C$7+$C$8*C34 -> 56 | G34: =$G$5 -> 31.142868 | H34: =$C$13+C34*$C$14 -> 30.822711
C35: 3.6 | D35: =$C$3-C$4*C35 -> 28 | E35: =$C$5+$C$6*C35 -> 46 | F35: =$C$7+$C$8*C35 -> 59 | G35: =$G$5 -> 31.142868 | H35: =$C$13+C35*$C$14 -> 32.316798
C36: 3.8 | D36: =$C$3-C$4*C36 -> 24 | E36: =$C$5+$C$6*C36 -> 48 | F36: =$C$7+$C$8*C36 -> 62 | G36: =$G$5 -> 31.142868 | H36: =$C$13+C36*$C$14 -> 33.810886
C37: 4 | D37: =$C$3-C$4*C37 -> 20 | E37: =$C$5+$C$6*C37 -> 50 | F37: =$C$7+$C$8*C37 -> 65 | G37: =$G$5 -> 31.142868 | H37: =$C$13+C37*$C$14 -> 35.304974
C38: 4.2 | D38: =$C$3-C$4*C38 -> 16 | E38: =$C$5+$C$6*C38 -> 52 | F38: =$C$7+$C$8*C38 -> 68 | G38: =$G$5 -> 31.142868 | H38: =$C$13+C38*$C$14 -> 36.799061
C39: 4.4 | D39: =$C$3-C$4*C39 -> 12 | E39: =$C$5+$C$6*C39 -> 54 | F39: =$C$7+$C$8*C39 -> 71 | G39: =$G$5 -> 31.142868 | H39: =$C$13+C39*$C$14 -> 38.293149
C40: 4.6 | D40: =$C$3-C$4*C40 -> 8 | E40: =$C$5+$C$6*C40 -> 56 | F40: =$C$7+$C$8*C40 -> 74 | G40: =$G$5 -> 31.142868 | H40: =$C$13+C40*$C$14 -> 39.787236
...

Sheet CPerf CON restriciones
H1: Competencia perfecta | L1: Oligopolio
B2: Competencia perfecta | H2: CSP | I2: =C3*E6-0.5*C4*E6^2-E6*G5 -> 118.53261 | L2: CSP | M2: =C3*E7-0.5*C4*E7^2-E7*G6 -> 65.187865
B3: PDMX | C3: 100 | D3: Qg1 | E3: 1.7 | F3: 1.7 | H3: PSP1 | I3: =E3*G5-(C5*E3+0.5*C6*E3*E3) -> 21.492876 | L3: PSP1 | M3: =G7*G6-(C6*G7+0.5*C6*G7*G7) -> 42.111817
B4: mD | C4: 20 | D4: Qg2 | E4: 1.7428566 | F4: 5 | H4: PSP2 | I4: =E4*G5-(C7*E4+0.5*C8*E4*E4) -> 22.781652 | J4: beta= | K4: =J5*2/E6 -> 25.719647 | L4: PSP2 | M4: =G8*G6-(C7*G8+0.5*C8*G8*G8) -> 43.335221
B5: PG1min | C5: 10 | E5: =SUM(E3:E4) -> 3.4428566 | F5: P* | G5: =C3-C4*E6 -> 31.142868 | H5: SW | I5: =SUM(I2:I4) -> 162.80714 | J5: =SUM(I3:I4) -> 44.274528 | L5: SW | M5: =SUM(M2:M4) -> 150.6349
B6: mO1 | C6: 10 | D6: Qd | E6: 3.4428566 | F6: Pm | G6: =Oligo!J16 -> 48.936171
B7: PG2min | C7: 5 | D7: Qm | E7: =G7+G8 -> 2.5531915 | F7: Qm1 | G7: =Oligo!J17 -> 1.2978723 | J7: Perdida de eficiencia | M7: =I5-M5 -> 12.17224
B8: mO2 | C8: 15 | F8: Qm2 | G8: =Oligo!J18 -> 1.2553191
B9: TC1 | C9: =C5*E3+0.5*C6*E3^2 -> 31.45
B10: TC2 | C10: =C7*E4+0.5*C8*E4^2 -> 31.495901
B11: U | C11: =C3*E6-0.5*C4*E6*E6 -> 225.75304
B12: SW | C12: =C11-C9-C10 -> 162.80714
B13: Pgmin eq | C13: =G5-K4 -> 5.4232213
B14: mOeq | C14: =K4/E6 -> 7.4704381
C16: Qg | D16: Bmarg | E16: MC1 | F16: MC2 | G16: P* | H16: eq | I16: Pm
C17: 0 | D17: =$C$3-C$4*C17 -> 100 | E17: =$C$5+$C$6*C17 -> 10 | F17: =$C$7+$C$8*C17 -> 5 | G17: =$G$5 -> 31.142868 | H17: =$C$13+C17*$C$14 -> 5.4232213 | I17: =Oligo!$J$16 -> 48.936171
C18: 0.2 | D18: =$C$3-C$4*C18 -> 96 | E18: =$C$5+$C$6*C18 -> 12 | F18: =$C$7+$C$8*C18 -> 8 | G18: =$G$5 -> 31.142868 | H18: =$C$13+C18*$C$14 -> 6.9173089 | I18: =Oligo!$J$16 -> 48.936171
C19: 0.4 | D19: =$C$3-C$4*C19 -> 92 | E19: =$C$5+$C$6*C19 -> 14 | F19: =$C$7+$C$8*C19 -> 11 | G19: =$G$5 -> 31.142868 | H19: =$C$13+C19*$C$14 -> 8.4113965 | I19: =Oligo!$J$16 -> 48.936171
C20: 0.6 | D20: =$C$3-C$4*C20 -> 88 | E20: =$C$5+$C$6*C20 -> 16 | F20: =$C$7+$C$8*C20 -> 14 | G20: =$G$5 -> 31.142868 | H20: =$C$13+C20*$C$14 -> 9.9054841 | I20: =Oligo!$J$16 -> 48.936171
C21: 0.8 | D21: =$C$3-C$4*C21 -> 84 | E21: =$C$5+$C$6*C21 -> 18 | F21: =$C$7+$C$8*C21 -> 17 | G21: =$G$5 -> 31.142868 | H21: =$C$13+C21*$C$14 -> 11.399572 | I21: =Oligo!$J$16 -> 48.936171
C22: 1 | D22: =$C$3-C$4*C22 -> 80 | E22: =$C$5+$C$6*C22 -> 20 | F22: =$C$7+$C$8*C22 -> 20 | G22: =$G$5 -> 31.142868 | H22: =$C$13+C22*$C$14 -> 12.893659 | I22: =Oligo!$J$16 -> 48.936171
C23: 1.2 | D23: =$C$3-C$4*C23 -> 76 | E23: =$C$5+$C$6*C23 -> 22 | F23: =$C$7+$C$8*C23 -> 23 | G23: =$G$5 -> 31.142868 | H23: =$C$13+C23*$C$14 -> 14.387747 | I23: =Oligo!$J$16 -> 48.936171
C24: 1.4 | D24: =$C$3-C$4*C24 -> 72 | E24: =$C$5+$C$6*C24 -> 24 | F24: =$C$7+$C$8*C24 -> 26 | G24: =$G$5 -> 31.142868 | H24: =$C$13+C24*$C$14 -> 15.881835 | I24: =Oligo!$J$16 -> 48.936171
C25: 1.6 | D25: =$C$3-C$4*C25 -> 68 | E25: =$C$5+$C$6*C25 -> 26 | F25: =$C$7+$C$8*C25 -> 29 | G25: =$G$5 -> 31.142868 | H25: =$C$13+C25*$C$14 -> 17.375922 | I25: =Oligo!$J$16 -> 48.936171
C26: 1.8 | D26: =$C$3-C$4*C26 -> 64 | E26: =$C$5+$C$6*C26 -> 28 | F26: =$C$7+$C$8*C26 -> 32 | G26: =$G$5 -> 31.142868 | H26: =$C$13+C26*$C$14 -> 18.87001 | I26: =Oligo!$J$16 -> 48.936171
C27: 2 | D27: =$C$3-C$4*C27 -> 60 | E27: =$C$5+$C$6*C27 -> 30 | F27: =$C$7+$C$8*C27 -> 35 | G27: =$G$5 -> 31.142868 | H27: =$C$13+C27*$C$14 -> 20.364097 | I27: =Oligo!$J$16 -> 48.936171
C28: 2.2 | D28: =$C$3-C$4*C28 -> 56 | E28: =$C$5+$C$6*C28 -> 32 | F28: =$C$7+$C$8*C28 -> 38 | G28: =$G$5 -> 31.142868 | H28: =$C$13+C28*$C$14 -> 21.858185 | I28: =Oligo!$J$16 -> 48.936171
... C30: 2.6 | D30: =$C$3-C$4*C30 -> 48 | E30: =$C$5+$C$6*C30 -> 36 | F30: =$C$7+$C$8*C30 -> 44 | G30: =$G$5 -> 31.142868 | H30: =$C$13+C30*$C$14 -> 24.84636 | I30: =Oligo!$J$16 -> 48.936171
C31: 2.8 | D31: =$C$3-C$4*C31 -> 44 | E31: =$C$5+$C$6*C31 -> 38 | F31: =$C$7+$C$8*C31 -> 47 | G31: =$G$5 -> 31.142868 | H31: =$C$13+C31*$C$14 -> 26.340448
C32: 3 | D32: =$C$3-C$4*C32 -> 40 | E32: =$C$5+$C$6*C32 -> 40 | F32: =$C$7+$C$8*C32 -> 50 | G32: =$G$5 -> 31.142868 | H32: =$C$13+C32*$C$14 -> 27.834535
C33: 3.2 | D33: =$C$3-C$4*C33 -> 36 | E33: =$C$5+$C$6*C33 -> 42 | F33: =$C$7+$C$8*C33 -> 53 | G33: =$G$5 -> 31.142868 | H33: =$C$13+C33*$C$14 -> 29.328623
C34: 3.4 | D34: =$C$3-C$4*C34 -> 32 | E34: =$C$5+$C$6*C34 -> 44 | F34: =$C$7+$C$8*C34 -> 56 | G34: =$G$5 -> 31.142868 | H34: =$C$13+C34*$C$14 -> 30.822711
C35: 3.6 | D35: =$C$3-C$4*C35 -> 28 | E35: =$C$5+$C$6*C35 -> 46 | F35: =$C$7+$C$8*C35 -> 59 | G35: =$G$5 -> 31.142868 | H35: =$C$13+C35*$C$14 -> 32.316798
C36: 3.8 | D36: =$C$3-C$4*C36 -> 24 | E36: =$C$5+$C$6*C36 -> 48 | F36: =$C$7+$C$8*C36 -> 62 | G36: =$G$5 -> 31.142868 | H36: =$C$13+C36*$C$14 -> 33.810886
C37: 4 | D37: =$C$3-C$4*C37 -> 20 | E37: =$C$5+$C$6*C37 -> 50 | F37: =$C$7+$C$8*C37 -> 65 | G37: =$G$5 -> 31.142868 | H37: =$C$13+C37*$C$14 -> 35.304974
C38: 4.2 | D38: =$C$3-C$4*C38 -> 16 | E38: =$C$5+$C$6*C38 -> 52 | F38: =$C$7+$C$8*C38 -> 68 | G38: =$G$5 -> 31.142868 | H38: =$C$13+C38*$C$14 -> 36.799061
C39: 4.4 | D39: =$C$3-C$4*C39 -> 12 | E39: =$C$5+$C$6*C39 -> 54 | F39: =$C$7+$C$8*C39 -> 71 | G39: =$G$5 -> 31.142868 | H39: =$C$13+C39*$C$14 -> 38.293149
C40: 4.6 | D40: =$C$3-C$4*C40 -> 8 | E40: =$C$5+$C$6*C40 -> 56 | F40: =$C$7+$C$8*C40 -> 74 | G40: =$G$5 -> 31.142868 | H40: =$C$13+C40*$C$14 -> 39.787236
C41: 4.8 | D41: =$C$3-C$4*C41 -> 4 | E41: =$C$5+$C$6*C41 -> 58 | F41: =$C$7+$C$8*C41 -> 77 | G41: =$G$5 -> 31.142868 | H41: =$C$13+C41*$C$14 -> 41.281324
C42: 5 | D42: =$C$3-C$4*C42 -> 0 | E42: =$C$5+$C$6*C42 -> 60 | F42: =$C$7+$C$8*C42 -> 80 | G42: =$G$5 -> 31.142868 | H42: =$C$13+C42*$C$14 -> 42.775412

Sheet Sheet1
A2: FCg | B2: 100 | C2: $h
L3: Ingresos | M3: Gastos | O3: Beneficio | P3: Gastos
B4: Pg | C4: TCg | D4: MagCost | E4: dem Curve | F4: AvgCost | H4: MargRev | I4: AvgRevenue | L4: Productor | M4: Productor | N4: PSP | O4: Cons | P4: Cons | Q4: CSP | R4: SW
B5: 0.1 | C5: =$B$2+B5*B5 -> 100.01 | D5: =2*B5 -> 0.2 | E5: =$B$15-($B$15/$B$16)*B5 -> 98 | F5: =$B$2/B5+B5 -> 1000.1 | H5: =$B$20-(2*$B$21-2)*B5 -> 96.2 | I5: =F5*B5 -> 100.01 | L5: =E5*B5 -> 9.8 | M5: =-C5 -> -100.01 | N5: =D5*B5-C5 -> -99.99 | O5: =$B$20*B5-0.5*$B$21*B5*B5 -> 9.9 | P5: =-B5*E5 -> -9.8 | Q5: =$B$20*B5-0.5*$B$21*B5*B5-B5*E5 -> 0.1 | R5: =N5+Q5 -> -99.89
B6: 1 | C6: =$B$2+B6*B6 -> 101 | D6: =2*B6 -> 2 | E6: =$B$15-($B$15/$B$16)*B6 -> 80 | F6: =$B$2/B6+B6 -> 101 | H6: =$B$20-(2*$B$21-2)*B6 -> 62 | I6: =F6*B6 -> 101 | L6: =E6*B6 -> 80 | M6: =-C6 -> -101 | N6: =E6*B6-C6 -> -21 | O6: =$B$20*B6-0.5*$B$21*B6*B6 -> 90 | P6: =-B6*E6 -> -80 | Q6: =$B$20*B6-0.5*$B$21*B6*B6-B6*E6 -> 10 | R6: =N6+Q6 -> -11
B7: 2 | C7: =$B$2+B7*B7 -> 104 | D7: =2*B7 -> 4 | E7: =$B$15-($B$15/$B$16)*B7 -> 60 | F7: =$B$2/B7+B7 -> 52 | H7: =$B$20-(2*$B$21-2)*B7 -> 24 | I7: =F7*B7 -> 104 | L7: =E7*B7 -> 120 | M7: =-C7 -> -104 | N7: =E7*B7-C7 -> 16 | O7: =$B$20*B7-0.5*$B$21*B7*B7 -> 160 | P7: =-B7*E7 -> -120 | Q7: =$B$20*B7-0.5*$B$21*B7*B7-B7*E7 -> 40 | R7: =N7+Q7 -> 56
B8: 3 | C8: =$B$2+B8*B8 -> 109 | D8: =2*B8 -> 6 | E8: =$B$15-($B$15/$B$16)*B8 -> 40 | F8: =$B$2/B8+B8 -> 36.333333 | H8: =$B$20-(2*$B$21-2)*B8 -> -14 | I8: =F8*B8 -> 109 | L8: =E8*B8 -> 120 | M8: =-C8 -> -109 | N8: =E8*B8-C8 -> 11 | O8: =$B$20*B8-0.5*$B$21*B8*B8 -> 210 | P8: =-B8*E8 -> -120 | Q8: =$B$20*B8-0.5*$B$21*B8*B8-B8*E8 -> 90 | R8: =N8+Q8 -> 101
B9: 4 | C9: =$B$2+B9*B9 -> 116 | D9: =2*B9 -> 8 | E9: =$B$15-($B$15/$B$16)*B9 -> 20 | F9: =$B$2/B9+B9 -> 29 | H9: =$B$20-(2*$B$21-2)*B9 -> -52 | I9: =F9*B9 -> 116 | L9: =E9*B9 -> 80 | M9: =-C9 -> -116 | N9: =E9*B9-C9 -> -36 | O9: =$B$20*B9-0.5*$B$21*B9*B9 -> 240 | P9: =-B9*E9 -> -80 | Q9: =$B$20*B9-0.5*$B$21*B9*B9-B9*E9 -> 160 | R9: =N9+Q9 -> 124
B10: 5 | C10: =$B$2+B10*B10 -> 125 | D10: =2*B10 -> 10 | E10: =$B$15-($B$15/$B$16)*B10 -> 0 | F10: =$B$2/B10+B10 -> 25 | H10: =$B$20-(2*$B$21-2)*B10 -> -90 | I10: =F10*B10 -> 125 | L10: =E10*B10 -> 0 | M10: =-C10 -> -125 | N10: =E10*B10-C10 -> -125 | O10: =$B$20*B10-0.5*$B$21*B10*B10 -> 250 | P10: =-B10*E10 -> 0 | Q10: =$B$20*B10-0.5*$B$21*B10*B10-B10*E10 -> 250 | R10: =N10+Q10 -> 125
B11: 6 | C11: =$B$2+B11*B11 -> 136 | D11: =2*B11 -> 12 | E11: =$B$15-($B$15/$B$16)*B11 -> -20 | F11: =$B$2/B11+B11 -> 22.666667 | H11: =$B$20-(2*$B$21-2)*B11 -> -128 | I11: =F11*B11 -> 136 | L11: =E11*B11 -> -120 | M11: =-C11 -> -136 | N11: =E11*B11-C11 -> -256 | O11: =$B$20*B11-0.5*$B$21*B11*B11 -> 240 | P11: =-B11*E11 -> 120 | Q11: =$B$20*B11-0.5*$B$21*B11*B11-B11*E11 -> 360 | R11: =N11+Q11 -> 104
B12: 7 | C12: =$B$2+B12*B12 -> 149 | D12: =2*B12 -> 14 | E12: =$B$15-($B$15/$B$16)*B12 -> -40 | F12: =$B$2/B12+B12 -> 21.285714 | H12: =$B$20-(2*$B$21-2)*B12 -> -166 | I12: =F12*B12 -> 149 | L12: =E12*B12 -> -280 | M12: =-C12 -> -149 | N12: =E12*B12-C12 -> -429 | O12: =$B$20*B12-0.5*$B$21*B12*B12 -> 210 | P12: =-B12*E12 -> 280 | Q12: =$B$20*B12-0.5*$B$21*B12*B12-B12*E12 -> 490 | R12: =N12+Q12 -> 61
A15: maxro | B15: 100
A16: maxPd | B16: 5
A18: Pd | B18: =B15/(B15/B16+2) -> 4.5454545
A19: ro | B19: =B15-(B15/B16)*B18 -> 9.0909091
A20: a | B20: =B15 -> 100
A21: b | B21: =B15/B16 -> 20
B31: =B18 -> 4.5454545 | C31: =$B$2+B31*B31 -> 120.66116 | D31: =2*B31 -> 9.0909091 | E31: =$B$15-($B$15/$B$16)*B31 -> 9.0909091 | F31: =$B$2/B31+B31 -> 26.545455 | H31: =$B$20-(2*$B$21-2)*B31 -> -72.727273 | I31: =F31*B31 -> 120.66116 | L31: =E31*B31 -> 41.322314 | M31: =-C31 -> -120.66116 | N31: =E31*B31-C31 -> -79.338843 | O31: =$B$20*B31-0.5*$B$21*B31*B31 -> 247.93388 | P31: =-B31*E31 -> -41.322314 | Q31: =$B$20*B31-0.5*$B$21*B31*B31-B31*E31 -> 206.61157 | R31: =N31+Q31 -> 127.27273
L37: =B20/(2*B21-2*1) -> 2.6315789
L38: =B20-B21*L37 -> 47.368421
L39: =2*L37 -> 5.2631579
L41: =(2.6-4.5)*(9.09-5.2)+ (2.6-4.5)*(47.3-9.09) -> -79.99
L43: =L41/R31 -> -0.62849286

Sheet Sheet2

Sheet Sheet3
E6: =(1-3/8)/2 -> 0.3125 | F6: =(1-E6)/2 -> 0.34375 | G6: =(1-F6)/2 -> 0.328125 | H6: =(1-G6)/2 -> 0.3359375 | I6: =(1-H6)/2 -> 0.33203125 | J6: =(1-I6)/2 -> 0.33398438 | K6: =(1-J6)/2 -> 0.33300781 | L6: =(1-K6)/2 -> 0.33349609 | M6: =(1-L6)/2 -> 0.33325195 | ... X6: =(1-W6)/2 -> 0.33333337

Sheet CPerf
H1: Competencia perfecta | L1: Oligopolio
B2: Competencia perfecta | H2: CSP | I2: =C3*E6-0.5*C4*E6^2-E6*G5 -> 125.2071 | L2: CSP | M2: =C3*E7-0.5*C4*E7^2-E7*G6 -> 65.187865 | P2: =C3*E6-0.5*C4*E6^2 -> 228.63905
B3: PDMX | C3: 100 | D3: Qg1 | E3: 1.9230769 | H3: PSP1 | I3: =E3*G5-(C5*E3+0.5*C6*E3*E3) -> 18.491124 | L3: PSP1 | M3: =G7*G6-(C6*G7+0.5*C6*G7*G7) -> 42.111817 | P3: =-(C5*E3+0.5*C6*E3*E3) -> -37.721894
B4: mD | C4: 20 | D4: Qg2 | E4: 1.6153846 | H4: PSP2 | I4: =E4*G5-(C7*E4+0.5*C8*E4*E4) -> 19.571006 | J4: beta= | K4: =J5*2/E6 -> 21.513378 | L4: PSP2 | M4: =G8*G6-(C7*G8+0.5*C8*G8*G8) -> 43.335221 | N4: =SUM(M3:M4) -> 85.447037 | P4: =-(C7*E4+0.5*C8*E4*E4) -> -27.647929
B5: PG1min | C5: 10 | E5: =SUM(E3:E4) -> 3.5384615 | F5: P* | G5: =C3-C4*E6 -> 29.230769 | H5: SW | I5: =SUM(I2:I4) -> 163.26923 | J5: =SUM(I3:I4) -> 38.06213 | L5: SW | M5: =SUM(M2:M4) -> 150.6349 | P5: =SUM(P2:P4) -> 163.26923 | Q5: =SUM(P3:P4) -> -65.369822
B6: mO1 | C6: 10 | D6: Qd | E6: 3.5384615 | F6: Pm | G6: =Oligo!J16 -> 48.936171
B7: PG2min | C7: 5 | D7: Qm | E7: =G7+G8 -> 2.5531915 | F7: Qm1 | G7: =Oligo!J17 -> 1.2978723 | J7: Perdida de eficiencia | M7: =I5-M5 -> 12.634328
B8: mO2 | C8: 15 | F8: Qm2 | G8: =Oligo!J18 -> 1.2553191
B9: TC1 | C9: =C5*E3+0.5*C6*E3^2 -> 37.721894
B10: TC2 | C10: =C7*E4+0.5*C8*E4^2 -> 27.647929 | E10: Multiplicador de Lagrange
B11: U | C11: =C3*E6-0.5*C4*E6*E6 -> 228.63905 | E11: l | F11: =G5 -> 29.230769 | G11: =C5+C6*F12-F11 -> 1.2232372e-07
B12: SW | C12: =C11-C9-C10 -> 163.26923 | E12: Q1 | F12: =E3 -> 1.9230769 | G12: =C7+C8*F13-F11 -> -2.4697031e-07
B13: Pgmin eq | C13: =G5-2*(I3+I4)/E6 -> 7.7173913 | E13: Q2 | F13: =E4 -> 1.6153846 | G13: =C3-C4*F14-F11 -> 0
B14: mOeq | C14: =(G5-C13)/E6 -> 6.0798677 | E14: QD | F14: =E6 -> 3.5384615 | G14: =F14-F13-F12 -> 4.8849813e-15
C16: Qg | D16: Bmarg | E16: MC1 | F16: MC2 | G16: P* | H16: eq | I16: Pm
C17: 0 | D17: =$C$3-C$4*C17 -> 100 | E17: =$C$5+$C$6*C17 -> 10 | F17: =$C$7+$C$8*C17 -> 5 | G17: =$G$5 -> 29.230769 | H17: =$C$13+C17*$C$14 -> 7.7173913 | I17: =Oligo!$J$16 -> 48.936171
C18: 0.2 | D18: =$C$3-C$4*C18 -> 96 | E18: =$C$5+$C$6*C18 -> 12 | F18: =$C$7+$C$8*C18 -> 8 | G18: =$G$5 -> 29.230769 | H18: =$C$13+C18*$C$14 -> 8.9333648 | I18: =Oligo!$J$16 -> 48.936171
C19: 0.4 | D19: =$C$3-C$4*C19 -> 92 | E19: =$C$5+$C$6*C19 -> 14 | F19: =$C$7+$C$8*C19 -> 11 | G19: =$G$5 -> 29.230769 | H19: =$C$13+C19*$C$14 -> 10.149338 | I19: =Oligo!$J$16 -> 48.936171
C20: 0.6 | D20: =$C$3-C$4*C20 -> 88 | E20: =$C$5+$C$6*C20 -> 16 | F20: =$C$7+$C$8*C20 -> 14 | G20: =$G$5 -> 29.230769 | H20: =$C$13+C20*$C$14 -> 11.365312 | I20: =Oligo!$J$16 -> 48.936171
C21: 0.8 | D21: =$C$3-C$4*C21 -> 84 | E21: =$C$5+$C$6*C21 -> 18 | F21: =$C$7+$C$8*C21 -> 17 | G21: =$G$5 -> 29.230769 | H21: =$C$13+C21*$C$14 -> 12.581285 | I21: =Oligo!$J$16 -> 48.936171 | L21: =2*G5-2*(I3+I4)/E6-G5 -> 7.7173913
C22: 1 | D22: =$C$3-C$4*C22 -> 80 | E22: =$C$5+$C$6*C22 -> 20 | F22: =$C$7+$C$8*C22 -> 20 | G22: =$G$5 -> 29.230769 | H22: =$C$13+C22*$C$14 -> 13.797259 | I22: =Oligo!$J$16 -> 48.936171
C23: 1.2 | D23: =$C$3-C$4*C23 -> 76 | E23: =$C$5+$C$6*C23 -> 22 | F23: =$C$7+$C$8*C23 -> 23 | G23: =$G$5 -> 29.230769 | H23: =$C$13+C23*$C$14 -> 15.013233 | I23: =Oligo!$J$16 -> 48.936171
C24: 1.4 | D24: =$C$3-C$4*C24 -> 72 | E24: =$C$5+$C$6*C24 -> 24 | F24: =$C$7+$C$8*C24 -> 26 | G24: =$G$5 -> 29.230769 | H24: =$C$13+C24*$C$14 -> 16.229206 | I24: =Oligo!$J$16 -> 48.936171
C25: 1.6 | D25: =$C$3-C$4*C25 -> 68 | E25: =$C$5+$C$6*C25 -> 26 | F25: =$C$7+$C$8*C25 -> 29 | G25: =$G$5 -> 29.230769 | H25: =$C$13+C25*$C$14 -> 17.44518 | I25: =Oligo!$J$16 -> 48.936171
C26: 1.8 | D26: =$C$3-C$4*C26 -> 64 | E26: =$C$5+$C$6*C26 -> 28 | F26: =$C$7+$C$8*C26 -> 32 | G26: =$G$5 -> 29.230769 | H26: =$C$13+C26*$C$14 -> 18.661153 | I26: =Oligo!$J$16 -> 48.936171
C27: 2 | D27: =$C$3-C$4*C27 -> 60 | E27: =$C$5+$C$6*C27 -> 30 | F27: =$C$7+$C$8*C27 -> 35 | G27: =$G$5 -> 29.230769 | H27: =$C$13+C27*$C$14 -> 19.877127 | I27: =Oligo!$J$16 -> 48.936171
C28: 2.2 | D28: =$C$3-C$4*C28 -> 56 | E28: =$C$5+$C$6*C28 -> 32 | F28: =$C$7+$C$8*C28 -> 38 | G28: =$G$5 -> 29.230769 | H28: =$C$13+C28*$C$14 -> 21.0931 | I28: =Oligo!$J$16 -> 48.936171
C29: 2.4 | D29: =$C$3-C$4*C29 -> 52 | E29: =$C$5+$C$6*C29 -> 34 | F29: =$C$7+$C$8*C29 -> 41 | G29: =$G$5 -> 29.230769 | H29: =$C$13+C29*$C$14 -> 22.309074 | I29: =Oligo!$J$16 -> 48.936171
C30: 2.6 | D30: =$C$3-C$4*C30 -> 48 | E30: =$C$5+$C$6*C30 -> 36 | F30: =$C$7+$C$8*C30 -> 44 | G30: =$G$5 -> 29.230769 | H30: =$C$13+C30*$C$14 -> 23.525047 | I30: =Oligo!$J$16 -> 48.936171
C31: 2.8 | D31: =$C$3-C$4*C31 -> 44 | E31: =$C$5+$C$6*C31 -> 38 | F31: =$C$7+$C$8*C31 -> 47 | G31: =$G$5 -> 29.230769 | H31: =$C$13+C31*$C$14 -> 24.741021
C32: 3 | D32: =$C$3-C$4*C32 -> 40 | E32: =$C$5+$C$6*C32 -> 40 | F32: =$C$7+$C$8*C32 -> 50 | G32: =$G$5 -> 29.230769 | H32: =$C$13+C32*$C$14 -> 25.956994
C33: 3.2 | D33: =$C$3-C$4*C33 -> 36 | E33: =$C$5+$C$6*C33 -> 42 | F33: =$C$7+$C$8*C33 -> 53 | G33: =$G$5 -> 29.230769 | H33: =$C$13+C33*$C$14 -> 27.172968
C34: 3.4 | D34: =$C$3-C$4*C34 -> 32 | E34: =$C$5+$C$6*C34 -> 44 | F34: =$C$7+$C$8*C34 -> 56 | G34: =$G$5 -> 29.230769 | H34: =$C$13+C34*$C$14 -> 28.388941
C35: 3.6 | D35: =$C$3-C$4*C35 -> 28 | E35: =$C$5+$C$6*C35 -> 46 | F35: =$C$7+$C$8*C35 -> 59 | G35: =$G$5 -> 29.230769 | H35: =$C$13+C35*$C$14 -> 29.604915
C36: 3.8 | D36: =$C$3-C$4*C36 -> 24 | E36: =$C$5+$C$6*C36 -> 48 | F36: =$C$7+$C$8*C36 -> 62 | G36: =$G$5 -> 29.230769 | H36: =$C$13+C36*$C$14 -> 30.820888
C37: 4 | D37: =$C$3-C$4*C37 -> 20 | E37: =$C$5+$C$6*C37 -> 50 | F37: =$C$7+$C$8*C37 -> 65 | G37: =$G$5 -> 29.230769 | H37: =$C$13+C37*$C$14 -> 32.036862
C38: 4.2 | D38: =$C$3-C$4*C38 -> 16 | E38: =$C$5+$C$6*C38 -> 52 | F38: =$C$7+$C$8*C38 -> 68 | G38: =$G$5 -> 29.230769 | H38: =$C$13+C38*$C$14 -> 33.252836
C39: 4.4 | D39: =$C$3-C$4*C39 -> 12 | E39: =$C$5+$C$6*C39 -> 54 | F39: =$C$7+$C$8*C39 -> 71 | G39: =$G$5 -> 29.230769 | H39: =$C$13+C39*$C$14 -> 34.468809
C40: 4.6 | D40: =$C$3-C$4*C40 -> 8 | E40: =$C$5+$C$6*C40 -> 56 | F40: =$C$7+$C$8*C40 -> 74 | G40: =$G$5 -> 29.230769 | H40: =$C$13+C40*$C$14 -> 35.684783
C41: 4.8 | D41: =$C$3-C$4*C41 -> 4 | E41: =$C$5+$C$6*C41 -> 58 | F41: =$C$7+$C$8*C41 -> 77 | G41: =$G$5 -> 29.230769 | H41: =$C$13+C41*$C$14 -> 36.900756
...

Sheet Oligo
B2: Competencia perfecta | I2: Oligopolio
B3: PDMX | C3: 100 | D3: Qg1 | E3: =J17 -> 1.2978723
B4: mD | C4: 20 | D4: Qg2 | E4: =J18 -> 1.2553191
B5: PG1min | C5: 10 | E5: =SUM(E3:E4) -> 2.5531915 | F5: P* | G5: =C3-C4*E6 -> 48.93617
B6: mO1 | C6: 10 | D6: Qd | E6: =J19 -> 2.5531915
B7: PG2min | C7: 5
B8: mO2 | C8: 15
B9: TC1 | C9: =C5*E3+0.5*C6*E3^2 -> 21.401086
B10: TC2 | C10: =C7*E4+0.5*C8*E4^2 -> 18.095292
B11: U | C11: =C3*E6-0.5*C4*E6*E6 -> 190.13128
B12: SW | C12: =C11-C9-C10 -> 150.6349
I16: Pm | J16: 48.936171 | K16: =C3-C4*(J17+J18) -> 48.93617
I17: Q1m | J17: 1.2978723 | K17: =C5+C6*J17+C4*J17 -> 48.93617
I18: Q2m | J18: 1.2553191 | K18: =C7+(C4+C8)*J18 -> 48.93617
J19: =SUM(J17:J18) -> 2.5531915
